Traceback (most recent call last):
  File "/opt/hostedtoolcache/Python/3.8.18/x64/lib/python3.8/site-packages/jupyter_cache/executors/utils.py", line 51, in single_nb_execution
    executenb(
  File "/opt/hostedtoolcache/Python/3.8.18/x64/lib/python3.8/site-packages/nbclient/client.py", line 1204, in execute
    return NotebookClient(nb=nb, resources=resources, km=km, **kwargs).execute()
  File "/opt/hostedtoolcache/Python/3.8.18/x64/lib/python3.8/site-packages/nbclient/util.py", line 84, in wrapped
    return just_run(coro(*args, **kwargs))
  File "/opt/hostedtoolcache/Python/3.8.18/x64/lib/python3.8/site-packages/nbclient/util.py", line 62, in just_run
    return loop.run_until_complete(coro)
  File "/opt/hostedtoolcache/Python/3.8.18/x64/lib/python3.8/asyncio/base_events.py", line 616, in run_until_complete
    return future.result()
  File "/opt/hostedtoolcache/Python/3.8.18/x64/lib/python3.8/site-packages/nbclient/client.py", line 663, in async_execute
    await self.async_execute_cell(
  File "/opt/hostedtoolcache/Python/3.8.18/x64/lib/python3.8/site-packages/nbclient/client.py", line 965, in async_execute_cell
    await self._check_raise_for_error(cell, cell_index, exec_reply)
  File "/opt/hostedtoolcache/Python/3.8.18/x64/lib/python3.8/site-packages/nbclient/client.py", line 862, in _check_raise_for_error
    raise CellExecutionError.from_cell_and_msg(cell, exec_reply_content)
nbclient.exceptions.CellExecutionError: An error occurred while executing the following cell:
------------------
import numpy as np
import matplotlib.pyplot as plt

# Add 1 mm diameter point
I0=np.linspace(10, 300, num=50)

# Scaling law
Rth=R_th_jc_ref*(I0/I0_ref)**(-1)

# plot
h, ax = plt.subplots(1,1,sharex=True)
ax.plot(I0, Rth, '--r',df['I0'],df['Rth_jc'],'.b', I0_ref, R_th_jc_ref, '.r')
ax.set_ylabel('Thermal resistance (junction to case) [Â°C/W]')
ax.set_xlabel('Rated current [A]')
ax.grid()
------------------

[0;31m---------------------------------------------------------------------------[0m
[0;31mNameError[0m                                 Traceback (most recent call last)
[0;32m/tmp/ipykernel_2235/2301627528.py[0m in [0;36m<cell line: 8>[0;34m()[0m
[1;32m      6[0m [0;34m[0m[0m
[1;32m      7[0m [0;31m# Scaling law[0m[0;34m[0m[0;34m[0m[0;34m[0m[0m
[0;32m----> 8[0;31m [0mRth[0m[0;34m=[0m[0mR_th_jc_ref[0m[0;34m*[0m[0;34m([0m[0mI0[0m[0;34m/[0m[0mI0_ref[0m[0;34m)[0m[0;34m**[0m[0;34m([0m[0;34m-[0m[0;36m1[0m[0;34m)[0m[0;34m[0m[0;34m[0m[0m
[0m[1;32m      9[0m [0;34m[0m[0m
[1;32m     10[0m [0;31m# plot[0m[0;34m[0m[0;34m[0m[0;34m[0m[0m

[0;31mNameError[0m: name 'R_th_jc_ref' is not defined
NameError: name 'R_th_jc_ref' is not defined

