Traceback (most recent call last):
  File "/opt/hostedtoolcache/Python/3.8.18/x64/lib/python3.8/site-packages/jupyter_cache/executors/utils.py", line 58, in single_nb_execution
    executenb(
  File "/opt/hostedtoolcache/Python/3.8.18/x64/lib/python3.8/site-packages/nbclient/client.py", line 1305, in execute
    return NotebookClient(nb=nb, resources=resources, km=km, **kwargs).execute()
  File "/opt/hostedtoolcache/Python/3.8.18/x64/lib/python3.8/site-packages/jupyter_core/utils/__init__.py", line 173, in wrapped
    return loop.run_until_complete(inner)
  File "/opt/hostedtoolcache/Python/3.8.18/x64/lib/python3.8/asyncio/base_events.py", line 616, in run_until_complete
    return future.result()
  File "/opt/hostedtoolcache/Python/3.8.18/x64/lib/python3.8/site-packages/nbclient/client.py", line 705, in async_execute
    await self.async_execute_cell(
  File "/opt/hostedtoolcache/Python/3.8.18/x64/lib/python3.8/site-packages/nbclient/client.py", line 1058, in async_execute_cell
    await self._check_raise_for_error(cell, cell_index, exec_reply)
  File "/opt/hostedtoolcache/Python/3.8.18/x64/lib/python3.8/site-packages/nbclient/client.py", line 914, in _check_raise_for_error
    raise CellExecutionError.from_cell_and_msg(cell, exec_reply_content)
nbclient.exceptions.CellExecutionError: An error occurred while executing the following cell:
------------------
def test_profiles(profil, step_size):
    tmin = 0
    time = np.array([])
    position = np.array([])
    speed = np.array([])
    acceleration = np.array([])
    for A, f, Nc in zip(profil.A, profil.f, profil.Nc):
        tmax = Nc / f
        # time vector
        t = np.arange(tmin, tmin + tmax, step_size)
        # Position, speed and Acceleration vectors
        X = A * np.sin(2 * pi * f * t)
        Xp = A * 2 * pi * f * np.cos(2 * pi * f * t)
        Xpp = -A * (2 * pi * f) ** 2 * np.sin(2 * pi * f * t)
        # Concatenation of multiple cycles
        time = np.concatenate((time, t))
        position = np.concatenate((position, X))
        speed = np.concatenate((speed, Xp))
        acceleration = np.concatenate((acceleration, Xpp))
        # new start time for the next cycle
        tmin = tmin + tmax

    d = {
        "t": time,
        "position": position,
        "speed": speed,
        "acceleration": acceleration,
    }

    df = pd.DataFrame(data=d)

    return df


df = test_profiles(profil, 1 / max(profil.f) / 20)

df
------------------


[0;31m---------------------------------------------------------------------------[0m
[0;31mAttributeError[0m                            Traceback (most recent call last)
[0;32m/tmp/ipykernel_2175/1604667484.py[0m in [0;36m?[0;34m()[0m
[0;32m---> 35[0;31m [0;32mdef[0m [0mtest_profiles[0m[0;34m([0m[0mprofil[0m[0;34m,[0m [0mstep_size[0m[0;34m)[0m[0;34m:[0m[0;34m[0m[0;34m[0m[0m
[0m[1;32m     36[0m     [0mtmin[0m [0;34m=[0m [0;36m0[0m[0;34m[0m[0;34m[0m[0m
[1;32m     37[0m     [0mtime[0m [0;34m=[0m [0mnp[0m[0;34m.[0m[0marray[0m[0;34m([0m[0;34m[[0m[0;34m][0m[0;34m)[0m[0;34m[0m[0;34m[0m[0m
[1;32m     38[0m     [0mposition[0m [0;34m=[0m [0mnp[0m[0;34m.[0m[0marray[0m[0;34m([0m[0;34m[[0m[0;34m][0m[0;34m)[0m[0;34m[0m[0;34m[0m[0m

[0;32m/opt/hostedtoolcache/Python/3.8.18/x64/lib/python3.8/site-packages/pandas/core/generic.py[0m in [0;36m?[0;34m(self, name)[0m
[1;32m   5898[0m             [0;32mand[0m [0mname[0m [0;32mnot[0m [0;32min[0m [0mself[0m[0;34m.[0m[0m_accessors[0m[0;34m[0m[0;34m[0m[0m
[1;32m   5899[0m             [0;32mand[0m [0mself[0m[0;34m.[0m[0m_info_axis[0m[0;34m.[0m[0m_can_hold_identifiers_and_holds_name[0m[0;34m([0m[0mname[0m[0;34m)[0m[0;34m[0m[0;34m[0m[0m
[1;32m   5900[0m         ):
[1;32m   5901[0m             [0;32mreturn[0m [0mself[0m[0;34m[[0m[0mname[0m[0;34m][0m[0;34m[0m[0;34m[0m[0m
[0;32m-> 5902[0;31m         [0;32mreturn[0m [0mobject[0m[0;34m.[0m[0m__getattribute__[0m[0;34m([0m[0mself[0m[0;34m,[0m [0mname[0m[0;34m)[0m[0;34m[0m[0;34m[0m[0m
[0m
[0;31mAttributeError[0m: 'DataFrame' object has no attribute 'f'

